<?xml version="1.0"?>
<robot name="navi">

 <material name="blue">
   <color rgba="0 0 1 1"/>
 </material>

<link name="base_link">
 <visual>
  <geometry>
   <box size="0.312 0.3 0.2"/>
  </geometry>
 <material name="blue"/>
 </visual>
 <collision>
  <geometry>
   <box size="0.312 0.3 0.2"/>
  </geometry>
 </collision> 
 <inertial>
   <mass value="5.0"/>
   <inertia ixx="0.1" iyy="0.1" izz="0.1" ixy="0" ixz="0" iyz="0"/>	 
 </inertial>
</link> 

<!-- Wheels -->
  <link name="front_left_wheel"/>
  <link name="front_right_wheel"/>
  <link name="rear_left_wheel"/>
  <link name="rear_right_wheel"/>

  <!-- Joints -->
  <joint name="front_left_wheel_joint" type="continuous">
    <parent link="base_link"/>
    <child link="front_left_wheel"/>
    <origin xyz="0.15 0.15 -0.05" rpy="0 0 0"/>
    <axis xyz="0 1 0"/>
  </joint>

  <joint name="front_right_wheel_joint" type="continuous">
    <parent link="base_link"/>
    <child link="front_right_wheel"/>
    <origin xyz="0.15 -0.15 -0.05" rpy="0 0 0"/>
    <axis xyz="0 1 0"/>
  </joint>

  <joint name="rear_left_wheel_joint" type="continuous">
    <parent link="base_link"/>
    <child link="rear_left_wheel"/>
    <origin xyz="-0.15 0.15 -0.05" rpy="0 0 0"/>
    <axis xyz="0 1 0"/>
  </joint>

  <joint name="rear_right_wheel_joint" type="continuous">
    <parent link="base_link"/>
    <child link="rear_right_wheel"/>
    <origin xyz="-0.15 -0.15 -0.05" rpy="0 0 0"/>
    <axis xyz="0 1 0"/>
  </joint>

</robot>
